{
    "type": "vulnerability",
    "spec_version": "2.1",
    "id": "vulnerability--6cfb564c-b8ad-4456-83bc-5b31189128b0",
    "created": "2024-08-13T16:03:35.333136Z",
    "modified": "2024-08-13T16:03:35.33314Z",
    "name": "No Title Available",
    "description": "In Python 3.8.4, sys.path restrictions specified in a python38._pth file are ignored, allowing code to be loaded from arbitrary locations. The <executable-name>._pth file (e.g., the python._pth file) is not affected.",
    "external_references": [
        {
            "source_name": "cve",
            "external_id": "CVE-2020-15801"
        }
    ],
    "references": [
        {
            "tags": [
                "x_refsource_MISC"
            ],
            "url": "https://bugs.python.org/issue41304"
        },
        {
            "tags": [
                "x_refsource_MISC"
            ],
            "url": "https://github.com/python/cpython/pull/21495"
        },
        {
            "tags": [
                "x_refsource_CONFIRM"
            ],
            "url": "https://security.netapp.com/advisory/ntap-20200731-0003/"
        }
    ]
}