{
    "type": "vulnerability",
    "spec_version": "2.1",
    "id": "vulnerability--173b3799-90d1-4faf-bcb1-eb17d3d658ce",
    "created": "2024-08-13T16:10:46.370061Z",
    "modified": "2024-08-13T16:10:46.370065Z",
    "name": "No Title Available",
    "description": "The ftp_QUIT function in ftpserver.py in pyftpdlib before 0.5.0 allows remote authenticated users to cause a denial of service (file descriptor exhaustion and daemon outage) by sending a QUIT command during a disallowed data-transfer attempt.",
    "external_references": [
        {
            "source_name": "cve",
            "external_id": "CVE-2008-7264"
        }
    ],
    "references": [
        {
            "tags": [
                "x_refsource_CONFIRM"
            ],
            "url": "http://code.google.com/p/pyftpdlib/source/detail?r=344"
        },
        {
            "tags": [
                "x_refsource_CONFIRM"
            ],
            "url": "http://code.google.com/p/pyftpdlib/source/browse/trunk/HISTORY"
        },
        {
            "tags": [
                "x_refsource_CONFIRM"
            ],
            "url": "http://code.google.com/p/pyftpdlib/source/diff?spec=svn344&r=344&format=side&path=/trunk/pyftpdlib/ftpserver.py"
        },
        {
            "tags": [
                "x_refsource_CONFIRM"
            ],
            "url": "http://code.google.com/p/pyftpdlib/issues/detail?id=71"
        }
    ]
}