{
    "type": "vulnerability",
    "spec_version": "2.1",
    "id": "vulnerability--ad4291a9-6e21-4efb-be23-c7a479753e1f",
    "created": "2024-08-13T16:02:47.627282Z",
    "modified": "2024-08-13T16:02:47.627286Z",
    "name": "No Title Available",
    "description": "An issue was discovered in the pyo3 crate before 0.12.4 for Rust. There is a reference-counting error and use-after-free in From<Py<T>>.",
    "external_references": [
        {
            "source_name": "cve",
            "external_id": "CVE-2020-35917"
        }
    ],
    "references": [
        {
            "tags": [
                "x_refsource_MISC"
            ],
            "url": "https://rustsec.org/advisories/RUSTSEC-2020-0074.html"
        }
    ]
}