{
    "type": "vulnerability",
    "spec_version": "2.1",
    "id": "vulnerability--ce790bb3-5b23-413b-a3fa-250c468d0ac7",
    "created": "2024-08-13T16:14:24.874101Z",
    "modified": "2024-08-13T16:14:24.874106Z",
    "name": "No Title Available",
    "description": "lib/ansible/playbook/__init__.py in Ansible 1.2.x before 1.2.3, when playbook does not run due to an error, allows local users to overwrite arbitrary files via a symlink attack on a retry file with a predictable name in /var/tmp/ansible/.",
    "external_references": [
        {
            "source_name": "cve",
            "external_id": "CVE-2013-4260"
        }
    ],
    "references": [
        {
            "tags": [
                "x_refsource_CONFIRM"
            ],
            "url": "https://groups.google.com/forum/#%21topic/ansible-project/UVDYW0HGcNg"
        },
        {
            "tags": [
                "x_refsource_CONFIRM"
            ],
            "url": "https://bugzilla.redhat.com/show_bug.cgi?id=998227"
        },
        {
            "name": "ansible-cve20134260-symlink(86898)",
            "tags": [
                "vdb-entry",
                "x_refsource_XF"
            ],
            "url": "https://exchange.xforce.ibmcloud.com/vulnerabilities/86898"
        },
        {
            "tags": [
                "x_refsource_CONFIRM"
            ],
            "url": "http://www.ansible.com/security"
        }
    ]
}